Workbook
Name Slicer_Should_I_Call?: #N/A

Sheet Registered
A1: =MAX(A3:A2026) -> 60 | B1: =COUNTIF(E3:E523,"Paused") -> 22 | C1: =COUNTIF(B3:B523,"To Resume") -> 6 | E1: =B1-C1 -> 16 | H1: =COUNTIF(I3:I523,"No Pay") -> 1 | I1: =COUNTIF(I3:I220,"Live") -> 29 | J1: =COUNTIF(E3:E523,"New") -> 5 | K1: =I1-J1-N1 -> -5 | N1: =COUNTIF(N2:N220,"Alert") -> 29 | O1: =COUNTIF(P2:Z207,"Yes") -> 162
A2: S/N | B2: Flag | C2: Name | D2: Module | E2: Doubt Flag | F2: Pause Remark | G2: Break Days | H2: Email | I2: Live | J2: Vintage | K2: Batch Timing | L2: Month# | M2: Day# | N2: Check! | O2: Class 1 Dt | P2: Fee 1 | Q2: Fee 2 | R2: Fee 3 | S2: Fee 4 | T2: Fee 5 | U2: Fee 6 | V2: Fee 7 | W2: Fee 8 | X2: Fee 9
A3: {=_xlfn.SEQUENCE(COUNTA(C3:C1048576))} -> 1 | C3: Soumya Verma (Amit) | E3: Live | G3: 40 | H3: soumyaamit84@gmail.com | I3: Paused | J3: =TODAY()-O3-G3 -> 471 | K3: Saturday 12:30pm | L3: =(J3-M3)/30 -> 15 | M3: =MOD(J3,30) -> 21 | N3: =IF(I3="No Pay","",IF(I3="Paused","",IF(L3="","",IF((COUNTIF(P3:AA3,"Yes"))-(COUNTIF(P3:AA3,"Pause"))<L3+1,"Alert","")))) | O3: 45668 | P3: Yes | Q3: Paused
A4: 2 | C4: Ravinder Rawal | E4: New | H4: rawalravindera@gmail.com | I4: Live | J4: =TODAY()-O4-G4 -> 503 | K4: SUNDAY 2pm | L4: =(J4-M4)/30 -> 16 | M4: =MOD(J4,30) -> 23 | N4: =IF(I4="No Pay","",IF(I4="Paused","",IF(L4="","",IF((COUNTIF(P4:AA4,"Yes"))-(COUNTIF(P4:AA4,"Pause"))<L4+1,"Alert","")))) -> Alert | O4: 45676 | P4: Yes | Q4: Yes | R4: Yes
A5: 3 | C5: Devesh Chauhan | E5: New | H5: deveshsinghchauhan01@gmail.com | I5: Live | J5: =TODAY()-O5-G5 -> 503 | K5: SUNDAY 2pm | L5: =(J5-M5)/30 -> 16 | M5: =MOD(J5,30) -> 23 | N5: =IF(I5="No Pay","",IF(I5="Paused","",IF(L5="","",IF((COUNTIF(P5:AA5,"Yes"))-(COUNTIF(P5:AA5,"Pause"))<L5+1,"Alert","")))) -> Alert | O5: 45676 | P5: Yes | Q5: Yes | R5: Yes
A6: 4 | C6: Bikash Shaw | E6: New | G6: 10 | H6: bikash242@yahoo.co.in | I6: Live | J6: =TODAY()-O6-G6 -> 493 | K6: SUNDAY 5pm | L6: =(J6-M6)/30 -> 16 | M6: =MOD(J6,30) -> 13 | N6: =IF(I6="No Pay","",IF(I6="Paused","",IF(L6="","",IF((COUNTIF(P6:AA6,"Yes"))-(COUNTIF(P6:AA6,"Pause"))<L6+1,"Alert","")))) -> Alert | O6: 45676 | P6: Yes
A7: 5 | B7: 1 | C7: Sonam Anand | D7: Power BI | E7: New | H7: sonam.anand0021@gmail.com | I7: Live | J7: =TODAY()-O7-G7 -> 496 | K7: SUNDAY 11am | L7: =(J7-M7)/30 -> 16 | M7: =MOD(J7,30) -> 16 | N7: =IF(I7="No Pay","",IF(I7="Paused","",IF(L7="","",IF((COUNTIF(P7:AA7,"Yes"))-(COUNTIF(P7:AA7,"Pause"))<L7+1,"Alert","")))) -> Alert | O7: 45683 | P7: Yes
A8: 6 | C8: Omkar Vaidya | D8: Power BI | E8: New | H8: omkarvaidya1@gmail.com | I8: Live | J8: =TODAY()-O8-G8 -> 482 | K8: SUNDAY 11am | L8: =(J8-M8)/30 -> 16 | M8: =MOD(J8,30) -> 2 | N8: =IF(I8="No Pay","",IF(I8="Paused","",IF(L8="","",IF((COUNTIF(P8:AA8,"Yes"))-(COUNTIF(P8:AA8,"Pause"))<L8+1,"Alert","")))) -> Alert | O8: 45697
A9: 7 | C9: Sakshi Pandey | E9: Live | H9: ssakshipandey2003@gmail.com | I9: Live | J9: =TODAY()-O9-G9 -> 503 | K9: SUNDAY 5pm | L9: =(J9-M9)/30 -> 16 | M9: =MOD(J9,30) -> 23 | N9: =IF(I9="No Pay","",IF(I9="Paused","",IF(L9="","",IF((COUNTIF(P9:AA9,"Yes"))-(COUNTIF(P9:AA9,"Pause"))<L9+1,"Alert","")))) -> Alert | O9: 45676 | P9: Yes | Q9: Yes | R9: Yes
A10: 8 | C10: Ritesh Kumar | E10: Live | H10: riteshkumar.nsn@gmail.com | I10: Paused | J10: =TODAY()-O10-G10 -> 503 | K10: SUNDAY 5pm | L10: =(J10-M10)/30 -> 16 | M10: =MOD(J10,30) -> 23 | N10: =IF(I10="No Pay","",IF(I10="Paused","",IF(L10="","",IF((COUNTIF(P10:AA10,"Yes"))-(COUNTIF(P10:AA10,"Pause"))<L10+1,"Alert","")))) | O10: 45676 | P10: Yes | Q10: Yes | R10: Paused
A11: 9 | C11: Monty Singh | E11: Live | H11: Montysingh456@gmail.com | I11: Live | J11: =TODAY()-O11-G11 -> 503 | K11: SUNDAY 5pm | L11: =(J11-M11)/30 -> 16 | M11: =MOD(J11,30) -> 23 | N11: =IF(I11="No Pay","",IF(I11="Paused","",IF(L11="","",IF((COUNTIF(P11:AA11,"Yes"))-(COUNTIF(P11:AA11,"Pause"))<L11+1,"Alert","")))) -> Alert | O11: 45676 | P11: Yes
A12: 10 | C12: Utkarsh Shah | E12: Live | H12: utkarshah05@gmail.com | I12: Live | J12: =TODAY()-O12-G12 -> 503 | K12: SUNDAY 5pm | L12: =(J12-M12)/30 -> 16 | M12: =MOD(J12,30) -> 23 | N12: =IF(I12="No Pay","",IF(I12="Paused","",IF(L12="","",IF((COUNTIF(P12:AA12,"Yes"))-(COUNTIF(P12:AA12,"Pause"))<L12+1,"Alert","")))) -> Alert | O12: 45676 | P12: Yes | Q12: Yes | R12: Yes
A13: 11 | C13: Siddhesh | E13: No | H13: sid.bruins@gmail.com | I13: Live | J13: =TODAY()-O13-G13 -> 503 | K13: SUNDAY 5pm | L13: =(J13-M13)/30 -> 16 | M13: =MOD(J13,30) -> 23 | N13: =IF(I13="No Pay","",IF(I13="Paused","",IF(L13="","",IF((COUNTIF(P13:AA13,"Yes"))-(COUNTIF(P13:AA13,"Pause"))<L13+1,"Alert","")))) -> Alert | O13: 45676 | P13: Yes | Q13: Yes | R13: Yes
A14: 12 | C14: Amrendra Singh | E14: Live | H14: singh_amrendra@rediffmail.com | I14: Paused | J14: =TODAY()-O14-G14 -> 517 | K14: SUNDAY 3-30pm | L14: =(J14-M14)/30 -> 17 | M14: =MOD(J14,30) -> 7 | N14: =IF(I14="No Pay","",IF(I14="Paused","",IF(L14="","",IF((COUNTIF(P14:AA14,"Yes"))-(COUNTIF(P14:AA14,"Pause"))<L14+1,"Alert","")))) | O14: 45662 | P14: Yes | Q14: Pause
A15: 13 | C15: Rajesh Jaiswal | E15: Live | H15: jacobsrajesh@gmail.com | I15: Paused | J15: =TODAY()-O15-G15 -> 517 | K15: SUNDAY 3-30pm | L15: =(J15-M15)/30 -> 17 | M15: =MOD(J15,30) -> 7 | N15: =IF(I15="No Pay","",IF(I15="Paused","",IF(L15="","",IF((COUNTIF(P15:AA15,"Yes"))-(COUNTIF(P15:AA15,"Pause"))<L15+1,"Alert","")))) | O15: 45662 | P15: Yes | Q15: Yes | R15: Pause
A16: 14 | B16: 1 | C16: Ishan Kotian | E16: No | H16: ishankotian081@gmail.com | I16: Paused | J16: =TODAY()-O16-G16 -> 517 | K16: SUNDAY 3-30pm | L16: =(J16-M16)/30 -> 17 | M16: =MOD(J16,30) -> 7 | N16: =IF(I16="No Pay","",IF(I16="Paused","",IF(L16="","",IF((COUNTIF(P16:AA16,"Yes"))-(COUNTIF(P16:AA16,"Pause"))<L16+1,"Alert","")))) | O16: 45662 | P16: Yes | Q16: Yes | R16: Yes | S16: Paused
A17: 15 | B17: 1 | C17: Shrishti Singh | E17: No | H17: singh.srishti2631@hotmail.com | I17: Live | J17: =TODAY()-O17-G17 -> 448 | K17: SUNDAY 3-30pm | L17: =(J17-M17)/30 -> 14 | M17: =MOD(J17,30) -> 28 | N17: =IF(I17="No Pay","",IF(I17="Paused","",IF(L17="","",IF((COUNTIF(P17:AA17,"Yes"))-(COUNTIF(P17:AA17,"Pause"))<L17+1,"Alert","")))) -> Alert | O17: 45731 | P17: Yes
A18: 16 | C18: Akshay Shah | E18: Paused | H18: Akshay02_shah@yahoo.co.in | I18: Paused | J18: =TODAY()-O18-G18 -> 559 | K18: SUNDAY 12-30pm | L18: =(J18-M18)/30 -> 18 | M18: =MOD(J18,30) -> 19 | N18: =IF(I18="No Pay","",IF(I18="Paused","",IF(L18="","",IF((COUNTIF(P18:AA18,"Yes"))-(COUNTIF(P18:AA18,"Pause"))<L18+1,"Alert","")))) | O18: 45620 | P18: Yes | Q18: Yes | R18: Yes | S18: Paused
A19: 17 | C19: Balgovind Pal | E19: No | H19: palbalgovind80@gmail.com | I19: Paused | J19: =TODAY()-O19-G19 -> 559 | K19: SUNDAY 12-30pm | L19: =(J19-M19)/30 -> 18 | M19: =MOD(J19,30) -> 19 | N19: =IF(I19="No Pay","",IF(I19="Paused","",IF(L19="","",IF((COUNTIF(P19:AA19,"Yes"))-(COUNTIF(P19:AA19,"Pause"))<L19+1,"Alert","")))) | O19: 45620 | P19: Yes | Q19: Yes | R19: Pause
A20: 18 | C20: Avanish Pathak | E20: No | H20: avanishpathak808@gmail.com | I20: Live | J20: =TODAY()-O20-G20 -> 552 | K20: Saturday 3pm | L20: =(J20-M20)/30 -> 18 | M20: =MOD(J20,30) -> 12 | N20: =IF(I20="No Pay","",IF(I20="Paused","",IF(L20="","",IF((COUNTIF(P20:AA20,"Yes"))-(COUNTIF(P20:AA20,"Pause"))<L20+1,"Alert","")))) -> Alert | O20: 45627 | P20: Yes | Q20: Yes | R20: Yes | S20: Yes | T20: Yes
A21: 19 | C21: Mahesh Sawant | D21: Power BI | E21: No | H21: Maheshtrigya79@gmail.com | I21: Paused | J21: =TODAY()-O21-G21 -> 552 | K21: SUNDAY 11am | L21: =(J21-M21)/30 -> 18 | M21: =MOD(J21,30) -> 12 | N21: =IF(I21="No Pay","",IF(I21="Paused","",IF(L21="","",IF((COUNTIF(P21:AA21,"Yes"))-(COUNTIF(P21:AA21,"Pause"))<L21+1,"Alert","")))) | O21: 45627 | P21: Yes | Q21: Pause
A22: 20 | B22: 1 | C22: Uttam Yamgar | E22: No | H22: uttamyamgar82@gmail.com | I22: Live | J22: =TODAY()-O22-G22 -> 546 | K22: Saturday 3pm | L22: =(J22-M22)/30 -> 18 | M22: =MOD(J22,30) -> 6 | N22: =IF(I22="No Pay","",IF(I22="Paused","",IF(L22="","",IF((COUNTIF(P22:AA22,"Yes"))-(COUNTIF(P22:AA22,"Pause"))<L22+1,"Alert","")))) -> Alert | O22: 45633 | P22: Yes | Q22: Yes
A23: 21 | C23: Abhay Sail | E23: No | G23: 15 | H23: abhay.sail21@gmail.com | I23: Live | J23: =TODAY()-O23-G23 -> 531 | K23: SUNDAY 3-30pm | L23: =(J23-M23)/30 -> 17 | M23: =MOD(J23,30) -> 21 | N23: =IF(I23="No Pay","",IF(I23="Paused","",IF(L23="","",IF((COUNTIF(P23:AA23,"Yes"))-(COUNTIF(P23:AA23,"Pause"))<L23+1,"Alert","")))) -> Alert | O23: 45633 | P23: Yes
A24: 22 | C24: Amrut Chavan | E24: No | H24: Amrut.chavan@kotak.com | I24: Live | J24: =TODAY()-O24-G24 -> 546 | K24: Saturday 3pm | L24: =(J24-M24)/30 -> 18 | M24: =MOD(J24,30) -> 6 | N24: =IF(I24="No Pay","",IF(I24="Paused","",IF(L24="","",IF((COUNTIF(P24:AA24,"Yes"))-(COUNTIF(P24:AA24,"Pause"))<L24+1,"Alert","")))) -> Alert | O24: 45633 | P24: Yes
A25: 23 | B25: 1 | C25: Sayali Gaikwad | E25: No | H25: sayalig077@gmail.com | I25: Live | J25: =TODAY()-O25-G25 -> 539 | K25: Saturday 3pm | L25: =(J25-M25)/30 -> 17 | M25: =MOD(J25,30) -> 29 | N25: =IF(I25="No Pay","",IF(I25="Paused","",IF(L25="","",IF((COUNTIF(P25:AA25,"Yes"))-(COUNTIF(P25:AA25,"Pause"))<L25+1,"Alert","")))) -> Alert | O25: 45640 | P25: Yes | Q25: Yes
A26: 24 | C26: Swapnil G | E26: No | H26: swapnil862@gmail.com | I26: Paused | J26: =TODAY()-O26-G26 -> 704 | K26: SUNDAY 9-30am | L26: =(J26-M26)/30 -> 23 | M26: =MOD(J26,30) -> 14 | N26: =IF(I26="No Pay","",IF(I26="Paused","",IF(L26="","",IF((COUNTIF(P26:AA26,"Yes"))-(COUNTIF(P26:AA26,"Pause"))<L26+1,"Alert","")))) | O26: 45475 | P26: Yes | Q26: Yes | R26: Yes | S26: Yes | T26: Yes | U26: Yes | V26: Yes | W26: Yes | X26: Paused
A27: 25 | B27: 1 | C27: Sourangshu M | E27: No | H27: sourangshu.maitra@gmail.com | I27: Live | J27: =TODAY()-O27-G27 -> 704 | K27: SUNDAY 12-30pm | L27: =(J27-M27)/30 -> 23 | M27: =MOD(J27,30) -> 14 | N27: =IF(I27="No Pay","",IF(I27="Paused","",IF(L27="","",IF((COUNTIF(P27:AA27,"Yes"))-(COUNTIF(P27:AA27,"Pause"))<L27+1,"Alert","")))) -> Alert | O27: 45475 | P27: Yes | Q27: Yes | R27: Yes | S27: Yes | T27: Yes | U27: Yes | V27: Yes | W27: Yes
A28: 26 | C28: Shailendra K | E28: No | H28: shailendra.khobaragade@gmail.com | I28: Live | J28: =TODAY()-O28-G28 -> 704 | K28: SUNDAY 9-30am | L28: =(J28-M28)/30 -> 23 | M28: =MOD(J28,30) -> 14 | N28: =IF(I28="No Pay","",IF(I28="Paused","",IF(L28="","",IF((COUNTIF(P28:AA28,"Yes"))-(COUNTIF(P28:AA28,"Pause"))<L28+1,"Alert","")))) -> Alert | O28: 45475 | P28: Yes | Q28: Yes | R28: Yes | S28: Yes | T28: Yes | U28: Yes | V28: Yes | W28: Yes | X28: Yes
A29: 27 | B29: 1 | C29: Harish S | E29: No | H29: harish_suri@hotmail.com | I29: Live | J29: =TODAY()-O29-G29 -> 699 | K29: SUNDAY 9-30am | L29: =(J29-M29)/30 -> 23 | M29: =MOD(J29,30) -> 9 | N29: =IF(I29="No Pay","",IF(I29="Paused","",IF(L29="","",IF((COUNTIF(P29:AA29,"Yes"))-(COUNTIF(P29:AA29,"Pause"))<L29+1,"Alert","")))) -> Alert | O29: 45480 | P29: Yes | Q29: Yes | R29: Yes | S29: Yes | T29: Yes | U29: Yes | V29: Yes | W29: Yes
A30: 28 | B30: 1 | C30: Kunal M | E30: No | H30: kunalmitramustaphi@gmail.com | I30: Live | J30: =TODAY()-O30-G30 -> 696 | K30: SUNDAY 9-30am | L30: =(J30-M30)/30 -> 23 | M30: =MOD(J30,30) -> 6 | N30: =IF(I30="No Pay","",IF(I30="Paused","",IF(L30="","",IF((COUNTIF(P30:AA30,"Yes"))-(COUNTIF(P30:AA30,"Pause"))<L30+1,"Alert","")))) -> Alert | O30: 45483 | P30: Yes | Q30: Yes | R30: Yes | S30: Yes | T30: Yes | U30: Yes | V30: Yes | W30: Yes
A31: 29 | B31: 1 | C31: Sagar G | E31: No | G31: 10 | H31: sagarg077@gmail.com | I31: Live | J31: =TODAY()-O31-G31 -> 689 | K31: SUNDAY 12-30pm | L31: =(J31-M31)/30 -> 22 | M31: =MOD(J31,30) -> 29 | N31: =IF(I31="No Pay","",IF(I31="Paused","",IF(L31="","",IF((COUNTIF(P31:AA31,"Yes"))-(COUNTIF(P31:AA31,"Pause"))<L31+1,"Alert","")))) -> Alert | O31: 45480 | P31: Yes | Q31: Yes | R31: Yes | S31: Yes | T31: Yes | U31: Yes | V31: Yes | W31: Yes
A32: 30 | B32: 1 | C32: Chris F | E32: No | H32: fernandeschris329@gmail.com | I32: Live | J32: =TODAY()-O32-G32 -> 699 | K32: SUNDAY 9-30am | L32: =(J32-M32)/30 -> 23 | M32: =MOD(J32,30) -> 9 | N32: =IF(I32="No Pay","",IF(I32="Paused","",IF(L32="","",IF((COUNTIF(P32:AA32,"Yes"))-(COUNTIF(P32:AA32,"Pause"))<L32+1,"Alert","")))) -> Alert | O32: 45480 | P32: Yes | Q32: Yes | R32: Yes | S32: Yes | T32: Yes | U32: Yes | V32: Yes | W32: Yes
A33: 31 | B33: 1 | C33: Mayank Pant | E33: No | H33: mayank_pant28@yahoo.co.in | I33: Live | J33: =TODAY()-O33-G33 -> 612 | K33: SUNDAY 9-30am | L33: =(J33-M33)/30 -> 20 | M33: =MOD(J33,30) -> 12 | N33: =IF(I33="No Pay","",IF(I33="Paused","",IF(L33="","",IF((COUNTIF(P33:AA33,"Yes"))-(COUNTIF(P33:AA33,"Pause"))<L33+1,"Alert","")))) -> Alert | O33: 45567 | P33: Yes | Q33: Yes | R33: Yes | S33: Yes | T33: Yes
A34: 32 | C34: Subhrangshu N | E34: No | G34: 90 | H34: subhrangsu.nath@gmail.com | I34: Live | J34: =TODAY()-O34-G34 -> 574 | K34: SUNDAY 11am | L34: =(J34-M34)/30 -> 19 | M34: =MOD(J34,30) -> 4 | N34: =IF(I34="No Pay","",IF(I34="Paused","",IF(L34="","",IF((COUNTIF(P34:AA34,"Yes"))-(COUNTIF(P34:AA34,"Pause"))<L34+1,"Alert","")))) -> Alert | O34: 45515 | P34: Yes
A35: 33 | C35: Amit V | E35: No | G35: 103 | H35: amitv0712@gmail.com | I35: Paused | J35: =TODAY()-O35-G35 -> 554 | K35: SUNDAY 12-30pm | L35: =(J35-M35)/30 -> 18 | M35: =MOD(J35,30) -> 14 | N35: =IF(I35="No Pay","",IF(I35="Paused","",IF(L35="","",IF((COUNTIF(P35:AA35,"Yes"))-(COUNTIF(P35:AA35,"Pause"))<L35+1,"Alert","")))) | O35: 45522 | P35: Yes | Q35: Pause
A36: 34 | B36: 1 | C36: Milton | E36: No | G36: 82 | H36: miltonsequeira06@gmail.com | I36: Live | J36: =TODAY()-O36-G36 -> 540 | K36: Saturday 2pm | L36: =(J36-M36)/30 -> 18 | M36: =MOD(J36,30) -> 0 | N36: =IF(I36="No Pay","",IF(I36="Paused","",IF(L36="","",IF((COUNTIF(P36:AA36,"Yes"))-(COUNTIF(P36:AA36,"Pause"))<L36+1,"Alert","")))) -> Alert | O36: 45557 | P36: Yes
A37: 35 | B37: 1 | C37: Nishant K | E37: No | G37: 50 | H37: p12nishantk@iimidr.ac.in | I37: Live | J37: =TODAY()-O37-G37 -> 607 | K37: SUNDAY 9-30am | L37: =(J37-M37)/30 -> 20 | M37: =MOD(J37,30) -> 7 | N37: =IF(I37="No Pay","",IF(I37="Paused","",IF(L37="","",IF((COUNTIF(P37:AA37,"Yes"))-(COUNTIF(P37:AA37,"Pause"))<L37+1,"Alert","")))) -> Alert | O37: 45522 | P37: Yes | Q37: Yes | R37: Yes | S37: Yes
A38: 36 | C38: Sagar (Hemant Sharma) | D38: GPT | E38: No | H38: Claimchase.sagar@gmail.com | I38: Live | J38: =TODAY()-O38-G38 -> 518 | K38: Saturday 11am | L38: =(J38-M38)/30 -> 17 | M38: =MOD(J38,30) -> 8 | N38: =IF(I38="No Pay","",IF(I38="Paused","",IF(L38="","",IF((COUNTIF(P38:AA38,"Yes"))-(COUNTIF(P38:AA38,"Pause"))<L38+1,"Alert","")))) -> Alert | O38: 45661 | P38: Yes | Q38: Yes
A39: 37 | C39: Hemant Sharma | D39: GPT | E39: No | G39: 111 | H39: hemant@manassolutions.com | I39: Live | J39: =TODAY()-O39-G39 -> 518 | K39: Saturday 11am | L39: =(J39-M39)/30 -> 17 | M39: =MOD(J39,30) -> 8 | N39: =IF(I39="No Pay","",IF(I39="Paused","",IF(L39="","",IF((COUNTIF(P39:AA39,"Yes"))-(COUNTIF(P39:AA39,"Pause"))<L39+1,"Alert","")))) -> Alert | O39: 45550 | P39: Yes | Q39: Yes | R39: Yes
A40: 38 | B40: 1 | C40: Ankita Rahate | E40: No | G40: 28 | H40: rahate_ankita@rediffmail.com | I40: Live | J40: =TODAY()-O40-G40 -> 504 | K40: SUNDAY 3-30pm | L40: =(J40-M40)/30 -> 16 | M40: =MOD(J40,30) -> 24 | N40: =IF(I40="No Pay","",IF(I40="Paused","",IF(L40="","",IF((COUNTIF(P40:AA40,"Yes"))-(COUNTIF(P40:AA40,"Pause"))<L40+1,"Alert","")))) -> Alert | O40: 45647 | P40: Yes
...

Sheet 08Aug2025
A1: =_xlfn.AGGREGATE(3,3,A3:A503) -> 73 | B1: ="Live : "&COUNTIF(C3:C503,"Existing") -> Live : 15 | C1: ="Should Call : "&COUNTIF(C3:C503,"Yes") -> Should Call : 40 | D1: ="Must Call :"&COUNTIF(D3:D503,"Yes") -> Must Call :23 | H1: ="Yes :"&COUNTIF(H3:H501,"Yes")&" No:"&(COUNTIF(H3:H501,"No")) -> Yes :11 No:2
A2: Name | B2: Prior Student? | C2: Should I Call? | D2: Must Call | E2: Potential Batch | F2: Website feedback | G2: LinkedIn Recommendations | H2: Class Start? | I2: Class Start Remark | J2: Refer?
A3: Utkarsh Shah | C3: Yes | D3: Yes | E3: Vive coding | H3: No | I3: November onwards may join
A4: Ravinder Rawal | C4: Yes | D4: Yes | E4: Excel | H4: No | I4: Will continue the excel batch
A5: Swapnil G | C5: Yes | D5: Yes | E5: Vive coding | H5: Yes | I5: 31Aug batch
A6: Chris F | C6: Yes | D6: Yes | E6: Vive coding | H6: Yes | I6: 31Aug batch
A7: Mayank Pant | C7: Yes | D7: Yes | E7: Vive coding | H7: Yes | I7: Not decided
A8: Sourav Chatterjee | B8: No | C8: Yes | D8: Yes | E8: Vive coding | H8: Yes | I8: 31st batch - PAID4
A9: Rohan Rege | B9: No | C9: Yes | D9: Yes | E9: Vive coding | H9: Yes | I9: 17Aug batch
A10: Neeraj Kumar | B10: No | C10: Yes | D10: Yes | E10: Vive coding | H10: Yes | I10: 31Aug batch
A11: Anuradha Mudgal | B11: No | C11: Yes | D11: Yes | E11: Agentic | H11: Yes | I11: 31st batch - PAID1
A12: Amrut Chavan | C12: Yes | D12: Yes | E12: Excel | H12: Yes | I12: 17Aug Excel batch
A13: Sourav C | C13: Yes | D13: Yes | E13: Vive coding | H13: Yes | I13: 31Aug batch
A14: Sayali Gaikwad | C14: Yes | D14: Yes | E14: Agentic | H14: Yes | I14: 31Aug batch
A15: Nishant K | C15: Yes | D15: Yes | E15: Agentic
A16: Sanjoy M | C16: Yes | D16: Yes | E16: Agentic
A17: Samuel Brainerd | C17: Yes | D17: Yes | E17: L&D - Chola
A18: Monty Singh | C18: Yes | D18: Yes | E18: Power BI
A19: Sonam Anand | C19: Yes | D19: Yes | E19: Vive coding
A20: Kunal M | C20: Yes | D20: Yes | E20: Vive coding
A21: Sagar G | C21: Yes | D21: Yes | E21: Vive coding
A22: Prashant Singh | B22: No | C22: Yes | D22: Yes | E22: Excel
A23: Stuti Upreti | C23: Yes | D23: Yes | E23: Excel
A24: Vaishali K | C24: Yes | D24: Yes | E24: Vive coding
A25: Ashish Suvarna | B25: No | C25: Yes | D25: Yes | E25: Vive coding
A26: Ankita Rahate | C26: Existing | D26: Existing | E26: Agentic | H26: Yes | I26: 17Aug batch
A27: Shrishti Singh | C27: Existing | D27: Existing | E27: Agentic
A28: Sourangshu M | C28: Existing | D28: Existing | E28: Agentic
A29: Shailendra K | C29: Existing | D29: Existing | E29: Agentic
A30: Harish S | C30: Existing | D30: Existing | E30: Agentic
A31: Milton | C31: Existing | D31: Existing | E31: Agentic
A32: Soniya Jha | C32: Existing | D32: Existing | E32: Agentic
A33: Sagar (Hemant Sharma) | C33: Existing | D33: Existing | E33: Agentic
A34: Hemant Sharma | C34: Existing | D34: Existing | E34: Agentic
A35: Subrata D | C35: Existing | D35: Existing | E35: Agentic
A36: Sachin K | C36: Existing | D36: Existing | E36: Agentic
A37: Rohan Sinha | C37: Existing | D37: Existing | E37: Agentic
A38: Anupam Pal | C38: Existing | D38: Existing | E38: Agentic
... A40: Sannjoy Biswas | C40: Existing | D40: Existing | E40: Agentic
A41: Sakshi Pandey | C41: Yes | E41: Agentic
...

Sheet Sheet2
A1: Potential Batch | B1: Name
A2: Vive coding | B2: Abhay Sail
B3: Ankita Rahate
B4: Avanish Pathak
B5: Bikash Shaw
B6: Chris F
B7: Ishan Kotian
B8: Kunal M
B9: Mahesh Sawant
B10: Mayank Pant
B11: Rajesh Gangan
B12: Rajesh Jaiswal
B13: Ritesh Kumar
B14: Rohan K
... B24: Vaishali K
A25: Agentic | B25: Nishant K
B26: Sakshi Pandey
B27: Sanjoy M
B28: Sayali Gaikwad
B29: Subhrangshu N
A30: Excel | B30: Amrut Chavan
B31: Ravinder Rawal
A32: Power BI | B32: Monty Singh
B33: Omkar Vaidya
A34: Basic Excel, PPT | B34: Soumya Verma (Amit)
A35: L&D - Chola | B35: Samuel Brainerd
A36: Grand Total

Sheet Segments
A1: =COUNTA(A3:A500) -> 62 | B1: =SUM(B3:B500) -> 17 | C1: =SUM(C3:C500) -> 1 | D1: =SUM(D3:D500) -> 5 | E1: =SUM(E3:E500) -> 8 | F1: =SUM(F3:F500) -> 30 | H1: 45766 | J1: =B1 -> 17 | K1: =C1 -> 1 | L1: =D1 -> 5 | M1: =E1 -> 8 | N1: =F1 -> 30
A2: Name | B2: Live | C2: Half Live | D2: May Join | E2: May Revive | F2: Dead | J2: Live | K2: Half Live | L2: May Join | M2: May Revive | N2: Dead
A3: Soumya Verma (Amit) | E3: 1 | J3: {=_xlfn._xlws.FILTER(A3:A64,B3:B64=1)} -> Ravinder Rawal | K3: {=_xlfn._xlws.FILTER(A3:A64,C3:C64=1)} -> Avanish Pathak | L3: {=_xlfn._xlws.FILTER(A3:A64,D3:D64=1)} -> Mrs Devesh Chauhan | M3: {=_xlfn._xlws.FILTER(A3:A64,E3:E64=1)} -> Soumya Verma (Amit) | N3: {=_xlfn._xlws.FILTER(A3:A64,F3:F64=1)} -> Sonam Anand
A4: Ravinder Rawal | B4: 1 | J4: Devesh Chauhan | L4: Omkar Vaidya | M4: Bikash Shaw | N4: Sakshi Pandey
A5: Devesh Chauhan | B5: 1 | J5: Utkarsh Shah | L5: Amrut Chavan | M5: Monty Singh | N5: Ritesh Kumar
A6: Mrs Devesh Chauhan | D6: 1 | J6: Siddhesh | L6: Sachin K | M6: Swapnil G | N6: Amrendra Singh
A7: Bikash Shaw | E7: 1 | J7: Shrishti Singh | L7: Sanjoy Ghosh | M7: Mayank Pant | N7: Rajesh Jaiswal
A8: Sonam Anand | F8: 1 | J8: Sayali Gaikwad | M8: Amit V | N8: Ishan Kotian
A9: Omkar Vaidya | D9: 1 | J9: Sourangshu M | M9: Nishant K | N9: Akshay Shah
A10: Sakshi Pandey | F10: 1 | J10: Shailendra K | M10: Sanjoy M | N10: Balgovind Pal
A11: Ritesh Kumar | D11: g7 | F11: 1 | J11: Harish S | N11: Mahesh Sawant
A12: Monty Singh | E12: 1 | J12: Kunal M | N12: Uttam Yamgar
A13: Utkarsh Shah | B13: 1 | J13: Sagar G | N13: Abhay Sail
A14: Siddhesh | B14: 1 | J14: Chris F | N14: Subhrangshu N
A15: Amrendra Singh | F15: 1 | J15: Milton | N15: Vaishali K
A16: Rajesh Jaiswal | F16: 1 | J16: Sagar (Hemant Sharma) | N16: Shreya S
A17: Ishan Kotian | F17: 1 | J17: Hemant Sharma | N17: Sachin J
A18: Shrishti Singh | B18: 1 | J18: Ankita Rahate | N18: Narinder Singh Sachdev
A19: Akshay Shah | F19: 1 | J19: Sourav C | N19: Anand K
A20: Balgovind Pal | F20: 1 | N20: Prashita T
A21: Avanish Pathak | C21: 1 | N21: Rajesh Pal
A22: Mahesh Sawant | F22: 1 | N22: Samuel Brainerd
A23: Uttam Yamgar | F23: 1 | N23: Ajinkyasing Paradeshi
A24: Abhay Sail | F24: 1 | N24: Rajesh Gangan
A25: Amrut Chavan | D25: 1 | N25: Ajay Sharma
A26: Sayali Gaikwad | B26: 1 | N26: Jitendra M
A27: Swapnil G | E27: 1 | N27: Rohit S
A28: Sourangshu M | B28: 1 | N28: Santosh F
A29: Shailendra K | B29: 1 | N29: Subir Choudhury
A30: Harish S | B30: 1 | N30: Rinkesh
A31: Kunal M | B31: 1 | N31: Suvajit R
A32: Sagar G | B32: 1 | N32: Rohan K
A33: Chris F | B33: 1
A34: Mayank Pant | E34: 1
A35: Subhrangshu N | F35: 1
A36: Amit V | E36: 1
A37: Milton | B37: 1
A38: Nishant K | E38: 1
A39: Sagar (Hemant Sharma) | B39: 1
A40: Hemant Sharma | B40: 1
...

Sheet March W1 Effort
E1: =E2/A3 -> 0.40983607 | I1: =I2/J3 -> 0.42424242 | J1: =J3/A3 -> 0.54098361
C2: =C3+B3 -> 3 | E2: =E3+D3 -> 25 | I2: =I3+H3 -> 14
A3: =COUNTA(A5:A65) -> 61 | B3: =SUM(B5:B65) -> 0 | C3: =SUM(C5:C65) -> 3 | D3: =SUM(D5:D65) -> 9 | E3: =SUM(E5:E65) -> 16 | F3: =SUM(F5:F65) -> 11 | G3: =SUM(G5:G65) -> 9 | H3: =SUM(H5:H65) -> 8 | I3: =SUM(I5:I65) -> 6 | J3: =SUM(J5:J65) -> 33
A4: Name | B4: Doubt Red | C4: Doubt Green | D4: Already Sleep | E4: Already Dead | F4: Live - Ask Pay | G4: Live - To Resume (March) | H4: Live - Paid Cycle | I4: Live - No Pay Reqd | J4: Positive | K4: P1 | L4: P2 | M4: Called 05Mar25?
A5: Soumya Verma (Amit) | G5: 1 | J5: =IF(SUM(F5:I5)>0,1,"") -> 1 | K5: 1 | M5: Last Week
A6: Ravinder Rawal | I6: 1 | J6: =IF(SUM(F6:I6)>0,1,"") -> 1
A7: Devesh Chauhan | I7: 1 | J7: =IF(SUM(F7:I7)>0,1,"") -> 1
A8: Bikash Shaw | F8: 1 | J8: =IF(SUM(F8:I8)>0,1,"") -> 1
A9: Sonam Anand | H9: 1 | J9: =IF(SUM(F9:I9)>0,1,"") -> 1
A10: Omkar Vaidya | G10: 1 | J10: =IF(SUM(F10:I10)>0,1,"") -> 1 | K10: 1 | M10: Last Week
A11: Sakshi Pandey | I11: 1 | J11: =IF(SUM(F11:I11)>0,1,"") -> 1 | M11: No Response
A12: Ritesh Kumar | C12: 1 | G12: 1 | J12: =IF(SUM(F12:I12)>0,1,"") -> 1 | K12: 1 | M12: Last Week
A13: Monty Singh | G13: 1 | J13: =IF(SUM(F13:I13)>0,1,"") -> 1 | K13: 1 | M13: Last Week
A14: Utkarsh Shah | I14: 1 | J14: =IF(SUM(F14:I14)>0,1,"") -> 1
A15: Siddhesh | I15: 1 | J15: =IF(SUM(F15:I15)>0,1,"") -> 1
A16: Amrendra Singh | E16: 1 | J16: =IF(SUM(F16:I16)>0,1,"")
A17: Rajesh Jaiswal | D17: 1 | J17: =IF(SUM(F17:I17)>0,1,"") | L17: 1
A18: Ishan Kotian | F18: 1 | J18: =IF(SUM(F18:I18)>0,1,"") -> 1
A19: Shirshti Singh | F19: 1
A20: Akshay Shah | D20: 1 | J20: =IF(SUM(F20:I20)>0,1,"")
A21: Balgovind Pal | D21: 1 | J21: =IF(SUM(F21:I21)>0,1,"") | L21: 1
A22: Avanish Pathak | H22: 1 | J22: =IF(SUM(F22:I22)>0,1,"") -> 1
A23: Mahesh Sawant | D23: 1 | J23: =IF(SUM(F23:I23)>0,1,"") | L23: 1 | M23: Msg Reply
A24: Uttam Yamgar | F24: 1 | J24: =IF(SUM(F24:I24)>0,1,"") -> 1 | M24: Call later
A25: Abhay Sail | J25: =IF(SUM(F25:I25)>0,1,"") | L25: 1
A26: Amrut Chavan | J26: =IF(SUM(F26:I26)>0,1,"") | L26: 1
A27: Sayali Gaikwad | F27: 1 | J27: =IF(SUM(F27:I27)>0,1,"") -> 1
A28: Swapnil G | F28: 1 | J28: =IF(SUM(F28:I28)>0,1,"") -> 1
A29: Sourangshu M | F29: 1 | J29: =IF(SUM(F29:I29)>0,1,"") -> 1
A30: Shailendra K | F30: 1 | J30: =IF(SUM(F30:I30)>0,1,"") -> 1
A31: Harish S | H31: 1 | J31: =IF(SUM(F31:I31)>0,1,"") -> 1
A32: Kunal M | H32: 1 | J32: =IF(SUM(F32:I32)>0,1,"") -> 1
A33: Sagar G | H33: 1 | J33: =IF(SUM(F33:I33)>0,1,"") -> 1
A34: Chris F | H34: 1 | J34: =IF(SUM(F34:I34)>0,1,"") -> 1
A35: Mayank Pant | H35: 1 | J35: =IF(SUM(F35:I35)>0,1,"") -> 1
A36: Subhrangshu N | I36: 1 | J36: =IF(SUM(F36:I36)>0,1,"") -> 1
A37: Amit V | D37: 1 | J37: =IF(SUM(F37:I37)>0,1,"") | L37: 1
A38: Milton | F38: 1 | J38: =IF(SUM(F38:I38)>0,1,"") -> 1
A39: Nishant K | G39: 1 | J39: =IF(SUM(F39:I39)>0,1,"") -> 1 | K39: 1
A40: Sagar (Hemant Sharma) | F40: 1 | J40: =IF(SUM(F40:I40)>0,1,"") -> 1
...

Sheet Alert List
A1: Main Page | B1: =COUNTA(B3:B28) -> 26 | D1: =COUNTIF(A3:A27,"Watch/Remove") -> 0 | E1: =COUNTIF(A3:A27,"Watch") -> 2 | G1: =D1+E1 -> 2
A2: Remark | B2: {=_xlfn.CHOOSECOLS(_xlfn.VSTACK(Registered!A2:O2),3,10,12,13)} -> Name | C2: Vintage | D2: Month# | E2: Day# | F2: Times Paid | G2: Months Gap
B3: {=_xlfn.CHOOSECOLS(_xlfn._xlws.SORT(_xlfn.VSTACK(_xlfn._xlws.FILTER(Registered!A3:O207,Registered!N3:N207="Alert")),13,-1),3,10,12,13)} -> Sayali Gaikwad | C3: 539 | D3: 17 | E3: 29 | F3: =IF(B3="","",COUNTIF(_xlfn.ANCHORARRAY(H3),"Yes")) -> 2 | G3: =IF(B3="","",(D3-F3+1)) -> 16 | H3: {=IF(B3="","",_xlfn.CHOOSECOLS(_xlfn.CHOOSEROWS(Registered!$C$14:$Z$207,MATCH('Alert List'!B3,Registered!$C$14:$C$207,0)),14,15,16,17,18,19,20,21,22,23,24))} -> Yes | I3: Yes | J3: 0 | K3: 0 | L3: 0 | M3: 0 | N3: 0 | O3: 0 | P3: 0 | Q3: 0 | R3: 0
A4: Watch | B4: Sagar G | C4: 689 | D4: 22 | E4: 29 | F4: =IF(B4="","",COUNTIF(_xlfn.ANCHORARRAY(H4),"Yes")) -> 8 | G4: =IF(B4="","",(D4-F4+1)) -> 15 | H4: {=IF(B4="","",_xlfn.CHOOSECOLS(_xlfn.CHOOSEROWS(Registered!$C$14:$Z$207,MATCH('Alert List'!B4,Registered!$C$14:$C$207,0)),14,15,16,17,18,19,20,21,22,23,24))} -> Yes | I4: Yes | J4: Yes | K4: Yes | L4: Yes | M4: Yes | N4: Yes | O4: Yes | P4: 0 | Q4: 0 | R4: 0
A5: Watch | B5: Shrishti Singh | C5: 448 | D5: 14 | E5: 28 | F5: =IF(B5="","",COUNTIF(_xlfn.ANCHORARRAY(H5),"Yes")) -> 1 | G5: =IF(B5="","",(D5-F5+1)) -> 14 | H5: {=IF(B5="","",_xlfn.CHOOSECOLS(_xlfn.CHOOSEROWS(Registered!$C$14:$Z$207,MATCH('Alert List'!B5,Registered!$C$14:$C$207,0)),14,15,16,17,18,19,20,21,22,23,24))} -> Yes | I5: 0 | J5: 0 | K5: 0 | L5: 0 | M5: 0 | N5: 0 | O5: 0 | P5: 0 | Q5: 0 | R5: 0
B6: Ankita Rahate | C6: 504 | D6: 16 | E6: 24 | F6: =IF(B6="","",COUNTIF(_xlfn.ANCHORARRAY(H6),"Yes")) -> 1 | G6: =IF(B6="","",(D6-F6+1)) -> 16 | H6: {=IF(B6="","",_xlfn.CHOOSECOLS(_xlfn.CHOOSEROWS(Registered!$C$14:$Z$207,MATCH('Alert List'!B6,Registered!$C$14:$C$207,0)),14,15,16,17,18,19,20,21,22,23,24))} -> Yes | I6: 0 | J6: 0 | K6: 0 | L6: 0 | M6: 0 | N6: 0 | O6: 0 | P6: 0 | Q6: 0 | R6: 0
B7: Ravinder Rawal | C7: 503 | D7: 16 | E7: 23 | F7: =IF(B7="","",COUNTIF(_xlfn.ANCHORARRAY(H7),"Yes")) -> 0 | G7: =IF(B7="","",(D7-F7+1)) -> 17 | H7: {=IF(B7="","",_xlfn.CHOOSECOLS(_xlfn.CHOOSEROWS(Registered!$C$14:$Z$207,MATCH('Alert List'!B7,Registered!$C$14:$C$207,0)),14,15,16,17,18,19,20,21,22,23,24))} -> #N/A
B8: Devesh Chauhan | C8: 503 | D8: 16 | E8: 23 | F8: =IF(B8="","",COUNTIF(_xlfn.ANCHORARRAY(H8),"Yes")) -> 0 | G8: =IF(B8="","",(D8-F8+1)) -> 17 | H8: {=IF(B8="","",_xlfn.CHOOSECOLS(_xlfn.CHOOSEROWS(Registered!$C$14:$Z$207,MATCH('Alert List'!B8,Registered!$C$14:$C$207,0)),14,15,16,17,18,19,20,21,22,23,24))} -> #N/A
B9: Sakshi Pandey | C9: 503 | D9: 16 | E9: 23 | F9: =IF(B9="","",COUNTIF(_xlfn.ANCHORARRAY(H9),"Yes")) -> 0 | G9: =IF(B9="","",(D9-F9+1)) -> 17 | H9: {=IF(B9="","",_xlfn.CHOOSECOLS(_xlfn.CHOOSEROWS(Registered!$C$14:$Z$207,MATCH('Alert List'!B9,Registered!$C$14:$C$207,0)),14,15,16,17,18,19,20,21,22,23,24))} -> #N/A
B10: Monty Singh | C10: 503 | D10: 16 | E10: 23 | F10: =IF(B10="","",COUNTIF(_xlfn.ANCHORARRAY(H10),"Yes")) -> 0 | G10: =IF(B10="","",(D10-F10+1)) -> 17 | H10: {=IF(B10="","",_xlfn.CHOOSECOLS(_xlfn.CHOOSEROWS(Registered!$C$14:$Z$207,MATCH('Alert List'!B10,Registered!$C$14:$C$207,0)),14,15,16,17,18,19,20,21,22,23,24))} -> #N/A
B11: Utkarsh Shah | C11: 503 | D11: 16 | E11: 23 | F11: =IF(B11="","",COUNTIF(_xlfn.ANCHORARRAY(H11),"Yes")) -> 0 | G11: =IF(B11="","",(D11-F11+1)) -> 17 | H11: {=IF(B11="","",_xlfn.CHOOSECOLS(_xlfn.CHOOSEROWS(Registered!$C$14:$Z$207,MATCH('Alert List'!B11,Registered!$C$14:$C$207,0)),14,15,16,17,18,19,20,21,22,23,24))} -> #N/A
B12: Siddhesh | C12: 503 | D12: 16 | E12: 23 | F12: =IF(B12="","",COUNTIF(_xlfn.ANCHORARRAY(H12),"Yes")) -> 0 | G12: =IF(B12="","",(D12-F12+1)) -> 17 | H12: {=IF(B12="","",_xlfn.CHOOSECOLS(_xlfn.CHOOSEROWS(Registered!$C$14:$Z$207,MATCH('Alert List'!B12,Registered!$C$14:$C$207,0)),14,15,16,17,18,19,20,21,22,23,24))} -> #N/A
B13: Abhay Sail | C13: 531 | D13: 17 | E13: 21 | F13: =IF(B13="","",COUNTIF(_xlfn.ANCHORARRAY(H13),"Yes")) -> 1 | G13: =IF(B13="","",(D13-F13+1)) -> 17 | H13: {=IF(B13="","",_xlfn.CHOOSECOLS(_xlfn.CHOOSEROWS(Registered!$C$14:$Z$207,MATCH('Alert List'!B13,Registered!$C$14:$C$207,0)),14,15,16,17,18,19,20,21,22,23,24))} -> Yes | I13: 0 | J13: 0 | K13: 0 | L13: 0 | M13: 0 | N13: 0 | O13: 0 | P13: 0 | Q13: 0 | R13: 0
B14: Sonam Anand | C14: 496 | D14: 16 | E14: 16 | F14: =IF(B14="","",COUNTIF(_xlfn.ANCHORARRAY(H14),"Yes")) -> 0 | G14: =IF(B14="","",(D14-F14+1)) -> 17 | H14: {=IF(B14="","",_xlfn.CHOOSECOLS(_xlfn.CHOOSEROWS(Registered!$C$14:$Z$207,MATCH('Alert List'!B14,Registered!$C$14:$C$207,0)),14,15,16,17,18,19,20,21,22,23,24))} -> #N/A
B15: Sourangshu M | C15: 704 | D15: 23 | E15: 14 | F15: =IF(B15="","",COUNTIF(_xlfn.ANCHORARRAY(H15),"Yes")) -> 8 | G15: =IF(B15="","",(D15-F15+1)) -> 16 | H15: {=IF(B15="","",_xlfn.CHOOSECOLS(_xlfn.CHOOSEROWS(Registered!$C$14:$Z$207,MATCH('Alert List'!B15,Registered!$C$14:$C$207,0)),14,15,16,17,18,19,20,21,22,23,24))} -> Yes | I15: Yes | J15: Yes | K15: Yes | L15: Yes | M15: Yes | N15: Yes | O15: Yes | P15: 0 | Q15: 0 | R15: 0
B16: Shailendra K | C16: 704 | D16: 23 | E16: 14 | F16: =IF(B16="","",COUNTIF(_xlfn.ANCHORARRAY(H16),"Yes")) -> 9 | G16: =IF(B16="","",(D16-F16+1)) -> 15 | H16: {=IF(B16="","",_xlfn.CHOOSECOLS(_xlfn.CHOOSEROWS(Registered!$C$14:$Z$207,MATCH('Alert List'!B16,Registered!$C$14:$C$207,0)),14,15,16,17,18,19,20,21,22,23,24))} -> Yes | I16: Yes | J16: Yes | K16: Yes | L16: Yes | M16: Yes | N16: Yes | O16: Yes | P16: Yes | Q16: 0 | R16: 0
B17: Bikash Shaw | C17: 493 | D17: 16 | E17: 13 | F17: =IF(B17="","",COUNTIF(_xlfn.ANCHORARRAY(H17),"Yes")) -> 0 | G17: =IF(B17="","",(D17-F17+1)) -> 17 | H17: {=IF(B17="","",_xlfn.CHOOSECOLS(_xlfn.CHOOSEROWS(Registered!$C$14:$Z$207,MATCH('Alert List'!B17,Registered!$C$14:$C$207,0)),14,15,16,17,18,19,20,21,22,23,24))} -> #N/A
B18: Avanish Pathak | C18: 552 | D18: 18 | E18: 12 | F18: =IF(B18="","",COUNTIF(_xlfn.ANCHORARRAY(H18),"Yes")) -> 5 | G18: =IF(B18="","",(D18-F18+1)) -> 14 | H18: {=IF(B18="","",_xlfn.CHOOSECOLS(_xlfn.CHOOSEROWS(Registered!$C$14:$Z$207,MATCH('Alert List'!B18,Registered!$C$14:$C$207,0)),14,15,16,17,18,19,20,21,22,23,24))} -> Yes | I18: Yes | J18: Yes | K18: Yes | L18: Yes | M18: 0 | N18: 0 | O18: 0 | P18: 0 | Q18: 0 | R18: 0
B19: Mayank Pant | C19: 612 | D19: 20 | E19: 12 | F19: =IF(B19="","",COUNTIF(_xlfn.ANCHORARRAY(H19),"Yes")) -> 5 | G19: =IF(B19="","",(D19-F19+1)) -> 16 | H19: {=IF(B19="","",_xlfn.CHOOSECOLS(_xlfn.CHOOSEROWS(Registered!$C$14:$Z$207,MATCH('Alert List'!B19,Registered!$C$14:$C$207,0)),14,15,16,17,18,19,20,21,22,23,24))} -> Yes | I19: Yes | J19: Yes | K19: Yes | L19: Yes | M19: 0 | N19: 0 | O19: 0 | P19: 0 | Q19: 0 | R19: 0
B20: Harish S | C20: 699 | D20: 23 | E20: 9 | F20: =IF(B20="","",COUNTIF(_xlfn.ANCHORARRAY(H20),"Yes")) -> 8 | G20: =IF(B20="","",(D20-F20+1)) -> 16 | H20: {=IF(B20="","",_xlfn.CHOOSECOLS(_xlfn.CHOOSEROWS(Registered!$C$14:$Z$207,MATCH('Alert List'!B20,Registered!$C$14:$C$207,0)),14,15,16,17,18,19,20,21,22,23,24))} -> Yes | I20: Yes | J20: Yes | K20: Yes | L20: Yes | M20: Yes | N20: Yes | O20: Yes | P20: 0 | Q20: 0 | R20: 0
B21: Chris F | C21: 699 | D21: 23 | E21: 9 | F21: =IF(B21="","",COUNTIF(_xlfn.ANCHORARRAY(H21),"Yes")) -> 8 | G21: =IF(B21="","",(D21-F21+1)) -> 16 | H21: {=IF(B21="","",_xlfn.CHOOSECOLS(_xlfn.CHOOSEROWS(Registered!$C$14:$Z$207,MATCH('Alert List'!B21,Registered!$C$14:$C$207,0)),14,15,16,17,18,19,20,21,22,23,24))} -> Yes | I21: Yes | J21: Yes | K21: Yes | L21: Yes | M21: Yes | N21: Yes | O21: Yes | P21: 0 | Q21: 0 | R21: 0
B22: Sourav C | C22: 579 | D22: 19 | E22: 9 | F22: =IF(B22="","",COUNTIF(_xlfn.ANCHORARRAY(H22),"Yes")) -> 5 | G22: =IF(B22="","",(D22-F22+1)) -> 15 | H22: {=IF(B22="","",_xlfn.CHOOSECOLS(_xlfn.CHOOSEROWS(Registered!$C$14:$Z$207,MATCH('Alert List'!B22,Registered!$C$14:$C$207,0)),14,15,16,17,18,19,20,21,22,23,24))} -> Yes | I22: Yes | J22: Yes | K22: Yes | L22: Yes | M22: 0 | N22: 0 | O22: 0 | P22: 0 | Q22: 0 | R22: 0
B23: Sagar (Hemant Sharma) | C23: 518 | D23: 17 | E23: 8 | F23: =IF(B23="","",COUNTIF(_xlfn.ANCHORARRAY(H23),"Yes")) -> 2 | G23: =IF(B23="","",(D23-F23+1)) -> 16 | H23: {=IF(B23="","",_xlfn.CHOOSECOLS(_xlfn.CHOOSEROWS(Registered!$C$14:$Z$207,MATCH('Alert List'!B23,Registered!$C$14:$C$207,0)),14,15,16,17,18,19,20,21,22,23,24))} -> Yes | I23: Yes | J23: 0 | K23: 0 | L23: 0 | M23: 0 | N23: 0 | O23: 0 | P23: 0 | Q23: 0 | R23: 0
B24: Hemant Sharma | C24: 518 | D24: 17 | E24: 8 | F24: =IF(B24="","",COUNTIF(_xlfn.ANCHORARRAY(H24),"Yes")) -> 3 | G24: =IF(B24="","",(D24-F24+1)) -> 15 | H24: {=IF(B24="","",_xlfn.CHOOSECOLS(_xlfn.CHOOSEROWS(Registered!$C$14:$Z$207,MATCH('Alert List'!B24,Registered!$C$14:$C$207,0)),14,15,16,17,18,19,20,21,22,23,24))} -> Yes | I24: Yes | J24: Yes | K24: 0 | L24: 0 | M24: 0 | N24: 0 | O24: 0 | P24: 0 | Q24: 0 | R24: 0
B25: Nishant K | C25: 607 | D25: 20 | E25: 7 | F25: =IF(B25="","",COUNTIF(_xlfn.ANCHORARRAY(H25),"Yes")) -> 4 | G25: =IF(B25="","",(D25-F25+1)) -> 17 | H25: {=IF(B25="","",_xlfn.CHOOSECOLS(_xlfn.CHOOSEROWS(Registered!$C$14:$Z$207,MATCH('Alert List'!B25,Registered!$C$14:$C$207,0)),14,15,16,17,18,19,20,21,22,23,24))} -> Yes | I25: Yes | J25: Yes | K25: Yes | L25: 0 | M25: 0 | N25: 0 | O25: 0 | P25: 0 | Q25: 0 | R25: 0
B26: Uttam Yamgar | C26: 546 | D26: 18 | E26: 6 | F26: =IF(B26="","",COUNTIF(_xlfn.ANCHORARRAY(H26),"Yes")) -> 2 | G26: =IF(B26="","",(D26-F26+1)) -> 17 | H26: {=IF(B26="","",_xlfn.CHOOSECOLS(_xlfn.CHOOSEROWS(Registered!$C$14:$Z$207,MATCH('Alert List'!B26,Registered!$C$14:$C$207,0)),14,15,16,17,18,19,20,21,22,23,24))} -> Yes | I26: Yes | J26: 0 | K26: 0 | L26: 0 | M26: 0 | N26: 0 | O26: 0 | P26: 0 | Q26: 0 | R26: 0
B27: Amrut Chavan | C27: 546 | D27: 18 | E27: 6 | F27: =IF(B27="","",COUNTIF(_xlfn.ANCHORARRAY(H27),"Yes")) -> 1 | G27: =IF(B27="","",(D27-F27+1)) -> 18 | H27: {=IF(B27="","",_xlfn.CHOOSECOLS(_xlfn.CHOOSEROWS(Registered!$C$14:$Z$207,MATCH('Alert List'!B27,Registered!$C$14:$C$207,0)),14,15,16,17,18,19,20,21,22,23,24))} -> Yes | I27: 0 | J27: 0 | K27: 0 | L27: 0 | M27: 0 | N27: 0 | O27: 0 | P27: 0 | Q27: 0 | R27: 0
B28: Kunal M | C28: 696 | D28: 23 | E28: 6 | F28: =IF(B28="","",COUNTIF(_xlfn.ANCHORARRAY(H28),"Yes")) -> 8 | G28: =IF(B28="","",(D28-F28+1)) -> 16 | H28: {=IF(B28="","",_xlfn.CHOOSECOLS(_xlfn.CHOOSEROWS(Registered!$C$14:$Z$207,MATCH('Alert List'!B28,Registered!$C$14:$C$207,0)),14,15,16,17,18,19,20,21,22,23,24))} -> Yes | I28: Yes | J28: Yes | K28: Yes | L28: Yes | M28: Yes | N28: Yes | O28: Yes | P28: 0 | Q28: 0 | R28: 0
B29: Subhrangshu N | C29: 574 | D29: 19 | E29: 4 | F29: =IF(B29="","",COUNTIF(_xlfn.ANCHORARRAY(H29),"Yes")) -> 1 | G29: =IF(B29="","",(D29-F29+1)) -> 19 | H29: {=IF(B29="","",_xlfn.CHOOSECOLS(_xlfn.CHOOSEROWS(Registered!$C$14:$Z$207,MATCH('Alert List'!B29,Registered!$C$14:$C$207,0)),14,15,16,17,18,19,20,21,22,23,24))} -> Yes | I29: 0 | J29: 0 | K29: 0 | L29: 0 | M29: 0 | N29: 0 | O29: 0 | P29: 0 | Q29: 0 | R29: 0
B30: Omkar Vaidya | C30: 482 | D30: 16 | E30: 2 | F30: =IF(B30="","",COUNTIF(_xlfn.ANCHORARRAY(H30),"Yes")) -> 0 | G30: =IF(B30="","",(D30-F30+1)) -> 17 | H30: {=IF(B30="","",_xlfn.CHOOSECOLS(_xlfn.CHOOSEROWS(Registered!$C$14:$Z$207,MATCH('Alert List'!B30,Registered!$C$14:$C$207,0)),14,15,16,17,18,19,20,21,22,23,24))} -> #N/A
B31: Milton | C31: 540 | D31: 18 | E31: 0 | G31: =IF(B31="","",(D31-F31+1)) -> 19 | H31: {=IF(B31="","",_xlfn.CHOOSECOLS(_xlfn.CHOOSEROWS(Registered!$C$14:$Z$207,MATCH('Alert List'!B31,Registered!$C$14:$C$207,0)),14,15,16,17,18,19,20,21,22,23,24))} -> Yes | I31: 0 | J31: 0 | K31: 0 | L31: 0 | M31: 0 | N31: 0 | O31: 0 | P31: 0 | Q31: 0 | R31: 0

Sheet Hot List
A1: Campaign | B1: Name | C1: Remark | D1: Remark 2 | E1: Action Point | F1: Remark 3
A2: {=_xlfn.CHOOSECOLS(_xlfn._xlws.FILTER(Table1[],Table1[Lead Status]="Follow"),2,5,6,7,8,9)} -> NewsInsert-05Jan25-3500 | B2: Om Prakash Sharma | C2: Confirmed | D2: om18.felix@gmail.com | E2: F/U for payment 6999/- | F2: Will call later, interested
A3: NewsInsert-05Jan25-3500 | B3: Siddhi Bankar | C3: 0 | D3: bankarsiddhi@gmail.com | E3: Call for confirmation | F3: Not confirmed
A4: NewsInsert-11Jan25-3500 | B4: Venugopal Pnakkal | C4: 0 | D4: 0 | E4: 0 | F4: 0
A5: NewsInsert-11Jan25-3500 | B5: Omkar Sawant | C5: Demo done, fu after a week | D5: 0 | E5: 0 | F5: 0
A6: Own Network | B6: Kartik (Madhu's son) | C6: 0 | D6: Am_madhu@rediffmail.com | E6: 0 | F6: 0
A7: Own Network | B7: Sachin's Son/Daughter | C7: 0 | D7: 0 | E7: 0 | F7: 0
A8: Akshay | B8: Akshay's friend | C8: 0 | D8: 0 | E8: 0 | F8: 0
A9: Uttam | B9: Priya Motwani | C9: 0 | D9: 0 | E9: 0 | F9: 0

Sheet Followups
A1: Call Dt. | B1: Campaign | C1: S/N | D1: Lead Status | E1: Name | F1: Remark | G1: Remark 2 | H1: Action Point | I1: Remark 3 | L1: =SUM(L3:L17) -> 45 | M1: =SUM(M3:M17) -> 11 | N1: =SUM(N3:N17) -> 34
B2: NewsInsert-05Jan25-3500 | C2: 1 | D2: Cold | E2: Shubham | F2: Doubtful | H2: Call for Kids batch, Drop | K2: Referee | L2: Expectation | M2: Already | N2: Balance
B3: NewsInsert-05Jan25-3500 | C3: 2 | D3: Convereted | E3: Siddhesh | F3: Confirmed, Paid 6999/- | H3: Send link | K3: Santosh | L3: 5 | M3: 1 | N3: =L3-M3 -> 4
B4: NewsInsert-05Jan25-3500 | C4: 3 | D4: Follow | E4: Om Prakash Sharma | F4: Confirmed | G4: om18.felix@gmail.com | H4: F/U for payment 6999/- | I4: Will call later, interested | K4: Shailendra | L4: 3 | M4: 1 | N4: =L4-M4 -> 2
B5: NewsInsert-05Jan25-3500 | C5: 4 | D5: Cold | E5: Asmita Bhat | F5: Not responding | H5: Call again, Drop | K5: Sourav C | L5: 6 | M5: 3 | N5: =L5-M5 -> 3
B6: NewsInsert-05Jan25-3500 | C6: 5 | D6: Convereted | E6: Ravinder Rawal | F6: Confirmed | H6: F/U for payment 6999/- | I6: Pay after demo | K6: Kunal M | L6: 4 | N6: =L6-M6 -> 4
B7: NewsInsert-05Jan25-3500 | C7: 6 | D7: Convereted | E7: Devesh Chavan | F7: Confirmed | H7: F/U for payment 6999/- | I7: Pay after demo | K7: Sourangshu | L7: 6 | M7: 3 | N7: =L7-M7 -> 3
B8: NewsInsert-05Jan25-3500 | C8: 7 | D8: Convereted | E8: Sakshi Pandey | F8: ssakshipandey2003@gmail.com | G8: to start from February | H8: F/U for email id & payment 6999/- | K8: Uttam | L8: 5 | M8: 2 | N8: =L8-M8 -> 3
B9: NewsInsert-05Jan25-3500 | C9: 8 | D9: Cold | E9: Niraj Tripathi | F9: Send Class link | G9: to pay after 1st session | H9: Call for email & name | K9: Sachin K | L9: 2 | N9: =L9-M9 -> 2
B10: NewsInsert-05Jan25-3500 | C10: 9 | D10: Follow | E10: Siddhi Bankar | G10: bankarsiddhi@gmail.com | H10: Call for confirmation | I10: Not confirmed | K10: Sanjoy M | L10: 5 | M10: 1 | N10: =L10-M10 -> 4
B11: NewsInsert-05Jan25-3500 | C11: 10 | D11: Cold | E11: Sneha Lembrekar | F11: Equiry done on whatsapp | H11: Call for confirmation | K11: Akshay | L11: 1 | N11: =L11-M11 -> 1
B12: NewsInsert-11Jan25-3500 | C12: 1 | D12: Convereted | E12: Ritesh Kumar | K12: Ajinkya | L12: 2 | N12: =L12-M12 -> 2
B13: NewsInsert-11Jan25-3500 | C13: 2 | D13: Follow | E13: Venugopal Pnakkal | K13: Sanjit | L13: 3 | N13: =L13-M13 -> 3
B14: NewsInsert-11Jan25-3500 | C14: 3 | D14: Convereted | E14: Utkarsh Shah | K14: Swapnil | L14: 3 | N14: =L14-M14 -> 3
B15: NewsInsert-11Jan25-3500 | C15: 4 | D15: Follow | E15: Omkar Sawant | F15: Demo done, fu after a week
B16: NewsInsert-11Jan25-3500 | C16: 5 | D16: Drop | E16: Rhutu Shah
B17: Own Network | D17: Follow | E17: Kartik (Madhu's son) | G17: Am_madhu@rediffmail.com
B18: Own Network | D18: Follow | E18: Sachin's Son/Daughter
B19: Akshay | D19: Follow | E19: Akshay's friend
B20: Uttam | D20: Follow | E20: Priya Motwani
B21: Self | D21: Cold | E21: Revathi
B22: Self | D22: Cold | E22: Abhishek P | F22: Abhi.praka@gmail.com
B23: Uttam | D23: Convereted | E23: Omkar Vaidya | F23: Business Analysis : Offline
B24: Santosh | E24: Ranjita Lodha
B25: Self | E25: Shruti
B26: Self | E26: Debasish
B27: Self | E27: Sanjoy Das
B28: Self | E28: Umesh Mondal
B29: Self | E29: Piyush Raghuwanshi | F29: Piyush.raghuwanshi@gmail.com | G29: From Feb'25
B30: Sourangshu M | E30: Vishal Purohit
B31: Sourangshu M | E31: Swarup
B32: Sourangshu M | E32: Kalpesh
B33: Sourangshu M | E33: Vikram Vyas
B34: Sourangshu M | E34: Sumit Gupta
B35: Sourangshu M | E35: Nanavati
B36: Sourangshu M | E36: Santosh
B37: Sunil | E37: Aditya Chillal
B38: Swapnil | D38: Coverted | E38: Monty Singh
B39: Self | E39: Prabhash
B40: Self | E40: Vara Prasad | F40: Power BI
...

Sheet Actionables
A1: Date of the though | B1: Category | C1: Task | D1: Sub-Task | E1: Start Date | F1: End Date | G1: Expenses | H1: Expected Outcome | AL1: Acquisition
A2: 45671 | B2: Acquisition | C2: Students from Classes | D2: Call Classes | E2: 45671 | H2: Get meetings | AL2: Retention
D3: Fix Meetings | E3: 45671 | H3: Understand the need | AL3: Engagement
D4: Make a Scheme/Structure : Course, duration, fees, Commission | H4: Get students | AL4: Class Followups
D5: Start hitting | AL5: Class Scheduling
A6: 45671 | B6: Class Scheduling | C6: Demo for Ritesh | D6: Call & Check today's availablity 5pm | E6: 45671 | AL6: Learning
A7: 45671 | B7: Class Scheduling | C7: Demo : Rhutu, Siddhi, Venugopal, Sneha, Om | D7: F/U for Demo, take dates | E7: 45671 | AL7: Preparation
A8: 45671 | B8: Preparation | C8: Python Class - today (1 Hour) | E8: 45671 | AL8: Question Paper
A9: 45671 | B9: Preparation | C9: Excel : Statistics (2 Hours) | E9: 45671 | AL9: Class Sessions
A10: 45671 | B10: Preparation | C10: PowerBI : Visualizations (1 Hour) | E10: 45671 | AL10: Reminder for Class
A11: 45671 | B11: Class Sessions | C11: Python Batch (8:30pm) | E11: 45671 | AL11: Payment Reminders
A12: 45671 | B12: Engagement | C12: Excel book for Amit | E12: 45671

Sheet Graphs
V2: Total Regn Till Date | W2: {=TRANSPOSE(_xlfn._xlws.FILTER(Registered!A1:O1,Registered!A1:O1<>""))} -> 60
V3: 2.1.Dropped | W3: 22 | Y3: {=_xlfn.VSTACK(_xlfn._xlws.SORT(V3:W10,1,-1))} -> Paid This Month | Z3: -5
V4: Break, To Resume | W4: 6 | Y4: Not Paying | Z4: 1
V5: Dead | W5: 16 | Y5: Not Paid This Month | Z5: 29
V6: Not Paying | W6: 1 | Y6: New, Yet To Pay | Z6: 5
V7: 1.1.Live & Paying | W7: 29 | Y7: Dead | Z7: 16
V8: New, Yet To Pay | W8: 5 | Y8: Break, To Resume | Z8: 6
V9: Paid This Month | W9: -5 | Y9: 2.1.Dropped | Z9: 22
V10: Not Paid This Month | W10: 29 | Y10: 1.1.Live & Paying | Z10: 29
V11: Total Paid Units | W11: 162
V16: Total Registered | W16: Live & Paying | X16: Paid This Month | Y16: =VLOOKUP(X16,_xlfn.ANCHORARRAY($Y$3),2,0) -> -5
V17: Total Registered | W17: Live & Paying | X17: Not Paid This Month | Y17: =VLOOKUP(X17,_xlfn.ANCHORARRAY($Y$3),2,0) -> 29
V18: Total Registered | W18: Live & Paying | X18: New, Yet To Pay | Y18: =VLOOKUP(X18,_xlfn.ANCHORARRAY($Y$3),2,0) -> 5
V19: Total Registered | W19: Live & Paying | X19: Not Paying | Y19: =VLOOKUP(X19,_xlfn.ANCHORARRAY($Y$3),2,0) -> 1
V20: Total Registered | W20: Dropped | X20: Break, To Resume | Y20: =VLOOKUP(X20,_xlfn.ANCHORARRAY($Y$3),2,0) -> 6
V21: Total Registered | W21: Dropped | X21: Dead | Y21: =VLOOKUP(X21,_xlfn.ANCHORARRAY($Y$3),2,0) -> 16
